Workbook

Sheet Controle
D2: Dashboard de Custos
D3: Itens | F3: Valor Total Previsto | G3: Valor Real
D4: Discrição | E4: Subiten
D5: Mão de Obra | E5: Mão de Obra | F5: =Dados!AA6 -> 6201141.8 | G5: =Dados!AB6 -> 6201141.8
D6: Equipamento | F6: =Dados!AA7 -> 1752644.5 | G6: =Dados!AB7 -> 1752644.5
E7: Onibus | F7: =Dados!AA8 -> 1309000 | G7: =Dados!AB8 -> 1309000
E8: Guindaste | F8: =Dados!AA9 -> 677.45676 | G8: =Dados!AB9 -> 677.45676
E9: Munck | F9: =Dados!AA10 -> 15499.329 | G9: =Dados!AB10 -> 15499.329
E10: Maquinas pesadas | F10: =Dados!AA11 -> 28252.644 | G10: =Dados!AB11 -> 3984.344
E11: Conteiner | F11: =Dados!AA12 -> 17677 | G11: =Dados!AB12 -> 17677
E12: Carros Leve | F12: =Dados!AA13 -> 234500 | G12: =Dados!AB13 -> 234500
E13: Outros | F13: =Dados!AA14 -> 14506.983 | G13: =Dados!AB14 -> 14506.983
D14: materiais | F14: =Dados!AA15 -> 88081.916 | G14: =Dados!AB15 -> 88081.916
E15: Ferramental | F15: =Dados!AA16 -> 4784.1478 | G15: =Dados!AB16 -> 4784.1478
E16: Consumiveis | F16: =Dados!AA17 -> 2292 | G16: =Dados!AB17 -> 2292
E17: Andamei | F17: =Dados!AA18 -> 1860.5202 | G17: =Dados!AB18 -> 1860.5202
E18: Caçamba | F18: =Dados!AA19 -> 329.88438 | G18: =Dados!AB19 -> 329.88438
E19: Outros | F19: =Dados!AA20 -> 82459.433 | G19: =Dados!AB20 -> 82459.433
D23: Total | F23: =SUM(F5:F19) -> 9753707.6 | G23: =SUM(G5:G19) -> 9729439.3

Sheet CPU
C5: GERAL
C7: SERVIÇO: | D7: Mobilização de equipe e equipamentos
C8: ITEM: | D8: 1.1.1.1.1 | F8: UNID.: | G8: vb | H8: 0
C9: ITEM | D9: DESCRIÇÃO | E9: UNID | F9: QUANTIDADE | G9: VALOR UNIT. | H9: VALOR TOTAL
C11: 1.0 | D11: MÃO DE OBRA
G13: 0
G14: 0 | H14: 0
C15: TOTAL 1.0 | H15: 0
C16: 2.0 | D16: EQUIPAMENTOS
G17: 0 | H17: 0
G18: 0 | H18: 0
G19: 0 | H19: 0
G20: 0 | H20: 0
G21: 0 | H21: 0
G22: 0 | H22: 0
G23: 0 | H23: 0
G24: 0 | H24: 0
C25: TOTAL 2.0 | H25: 0
C26: 3.0 | D26: MATERIAIS | H26: 0
G27: 0 | H27: 0
G28: 0 | H28: 0
G29: 0 | H29: 0
G30: 0 | H30: 0
G31: 0 | H31: 0
G32: 0 | H32: 0
G33: 0 | H33: 0
C34: TOTAL 3.0 | H34: 0
C35: CUSTO DIRETO (A+B+C) | H35: 0
C36: BDI | H36: 0
C37: TOTAL GERAL | H37: 0
C39: SERVIÇO: | D39: Desmobilização de equipe e equipamentos
C40: ITEM: | D40: 1.1.1.1.2 | F40: UNID.: | G40: vb | H40: 268104.35
C41: ITEM | D41: DESCRIÇÃO | E41: UNID | F41: QUANTIDADE | G41: VALOR UNIT. | H41: VALOR TOTAL
C43: 1.0 | D43: MÃO DE OBRA
C44: MOD | D44: Mecânico montador | E44: h | F44: 330 | G44: 79.456006 | H44: 26220.482
C45: MOD | D45: Ajudante de montagem | E45: h | F45: 330 | G45: 45.411751 | H45: 14985.878
G46: 0 | H46: 0
G47: 0 | H47: 0
C48: TOTAL 1.0 | H48: =H44+H45 -> 41206.36
C49: 2.0 | D49: EQUIPAMENTOS
...

Sheet Dados
A1: Dados JL
F3: Mês
A4: Itens | B4: Descrição | C4: Sub-Grupo | D4: Total previsto | E4: Total real | F4: 46113 | G4: 46143 | H4: 46174 | I4: 46204 | J4: 46235 | K4: 46266 | L4: 46296 | M4: 46327 | N4: 46357 | O4: 46388 | P4: 46419 | Q4: 46447 | R4: 46478 | S4: 46508 | T4: 46539 | U4: 46569 | V4: Total Custo | Y4: Itens
A5: 1.1.1.1.1 | B5: Mobilização de equipe e equipamentos | D5: 0 | E5: =D5-V5 -> 0 | G5: =Controle!I5 -> 0 | H5: =Controle!J5 -> 0 | I5: =Controle!K5 -> 0 | J5: =Controle!L5 -> 0 | K5: =Controle!M5 -> 0 | L5: =Controle!N5 -> 0 | M5: =Controle!O5 -> 0 | N5: =Controle!P5 -> 0 | ... U5: =Controle!W5 -> 0 | V5: =SUM(F5:U5) -> 0 | Y5: Discrição | Z5: Subiten | AA5: Valor total | AB5: Valor Atual
A6: 1.1.1.1.2 | B6: Desmobilização de equipe e equipamentos | D6: =SUM(D7:D9) -> 215111.36 | E6: =D6-V6 -> 215111.36 | V6: =SUM(F6:U6) -> 0 | Y6: Mão de Obra | Z6: Mão de Obra | AA6: =SUM(D7+D12+D21+D26+D31+D35+D39+D43+D47+D52+D62+D72+D86+D103+D120+D136+D142+D148+D154+D160+D166+D172+D176+D180+D184+D188+D192+D199+D209+D219+D229+D239+D245+D251+D257+D263+D269+D275+D281+D288+D295+D302+D309+D316+D323+D329) -> 6201141.8 | AB6: =SUM(E7+E12+E21+E26+E31+E35+E39+E43+E47+E52+E62+E72+E86+E103+E120+E136+E142+E148+E154+E160+E166+E172+E176+E180+E184+E188+E192+E199+E209+E219+E229+E239+E245+E251+E257+E263+E269+E275+E281+E288+E295+E302+E309+E316+E323+E329) -> 6201141.8
B7: MÃO DE OBRA | C7: Mão de Obra | D7: 41206.36 | E7: =D7-V7 -> 41206.36 | V7: =SUM(F7:U7) -> 0 | Y7: Equipamento | AA7: =SUM(D8+D13+D22+D28+D32+D36+D40+D44+D48+D53+D63+D63+D73+D87+D104+D121+D137+D143+D149+D155+D161+D167+D173+D177+D181+D185+D189+D193+D200+D210+D220+D230+D240+D246+D252+D258+D264+D270+D276+D282+D289+D296+D303+D310+D317+D324) -> 1752644.5 | AB7: =SUM(E8+E13+E22+E28+E32+E36+E40+E44+E48+E53+E63+E63+E73+E87+E104+E121+E137+E143+E149+E155+E161+E167+E173+E177+E181+E185+E189+E193+E200+E210+E220+E230+E240+E246+E252+E258+E264+E270+E276+E282+E289+E296+E303+E310+E317+E324) -> 1752644.5
B8: EQUIPAMENTOS | C8: REPAROS E IDENIZAÇÕES EM EQUIPAMENTOS DE PEQUENO E MÉDIO PORTE | D8: 100000 | E8: =D8-V8 -> 100000 | V8: =SUM(F8:U8) -> 0 | Z8: Onibus | AA8: =SUM(D23) -> 1309000 | AB8: =SUM(E23) -> 1309000
B9: MATERIAIS | C9: Equipe MOD | Equipe MOI | D9: 73905 | E9: =D9-V9 -> 73905 | V9: =SUM(F9:U9) -> 0 | Z9: Guindaste | AA9: =SUM(D55+D65+D75+D89+D106+D123) -> 677.45676 | AB9: =SUM(E55+E65+E75+E89+E106+E123) -> 677.45676
A10: 1.2.1.1 | B10: Construção de Canteiro Completo (Adm, Vestiários, Refeitório, Armazém, etc) | D10: 0 | E10: =D10-V10 -> 0 | V10: =SUM(F10:U10) -> 0 | Z10: Munck | AA10: =SUM(D54+D64+D74+D88+D105+D122+D201+D211+D221+D231+D326) -> 15499.329 | AB10: =SUM(E54+E64+E74+E88+E105+E122+E201+E211+E221+E231+E326) -> 15499.329
A11: 1.2.1.2 | B11: Administração e Manutenção de Canteiro | D11: =SUM(D17,D13,D12) -> 98626.543 | E11: =D11-V11 -> 98626.543 | V11: =SUM(F11:U11) -> 0 | Z11: Maquinas pesadas | AA11: =SUM(D36+D40+D44+D56+D66+D77+D78+D79+D91+D92+D93+D94+D108+D109+D110+D125+D111+D126+D127+D16) -> 28252.644 | AB11: =SUM(E36+E40+E44+E56+E66+E77+E78+E79+E91+E92+E93+E94+E108+E109+E110+E125+E111+E126+E127) -> 3984.344
B12: MÃO DE OBRA | C12: MÃO DE OBRA | D12: 5931.2396 | E12: =D12-V12 -> 5931.2396 | V12: =SUM(F12:U12) -> 0 | Z12: Conteiner | AA12: =SUM(D14) -> 17677 | AB12: =SUM(E14) -> 17677
B13: EQUIPAMENTOS | C13: EQUIPAMENTOS | D13: 56745.303 | E13: =D13-V13 -> 56745.303 | V13: =SUM(F13:U13) -> 0 | Z13: Carros Leve | AA13: =D24 -> 234500 | AB13: =E24 -> 234500
B14: Contêines | C14: Contêiner | D14: 17677 | E14: =D14-V14 -> 17677 | V14: =SUM(F14:U14) -> 0 | Z14: Outros | AA14: =SUM(D15,D76,D90,D107,D124,D194,D202,D203,D212,D213,D222,D223,D232,D233,D283,D290,D297,D304,D311,D318,D325) -> 14506.983 | AB14: =SUM(E15,E76,E90,E107,E124,E194,E202,E203,E212,E213,E222,E223,E232,E233,E283,E290,E297,E304,E311,E318,E325) -> 14506.983
B15: Banheiro | C15: Banheiros hidráulicos | D15: 8850 | E15: =D15-V15 -> 8850 | V15: =SUM(F15:U15) -> 0 | Y15: materiais | AA15: =SUM(D17+D25+D29+D33+D37+D41+D45+D57+D67+D80+D95+D112+D128+D138+D144+D150+D156+D162+D168+D174+D178+D182+D186+D195+D190+D204+D214+D224+D234+D241+D247+D253+D259+D265+D271+D277+D284+D291+D298+D305+D312+D319+D327) -> 88081.916 | AB15: =SUM(E17+E25+E29+E33+E37+E41+E45+E57+E67+E80+E95+E112+E128+E138+E144+E150+E156+E162+E168+E174+E178+E182+E186+E195+E190+E204+E214+E224+E234+E241+E247+E253+E259+E265+E271+E277+E284+E291+E298+E305+E312+E319+E327) -> 88081.916
B16: Maquinas Pesadas | C16: Caminhão pipa com operador | D16: 24268.3 | E16: =D16-V16 -> 24268.3 | V16: =SUM(F16:U16) -> 0 | Z16: Ferramental | AA16: =SUM(D325,D318,D311,D304,D297,D290,D283,D235,D232,D225,D222,D58,D68,D76,D81,D90,D96,D107,D113+D124,D129,D194,D202,D205,D212,D215) -> 4784.1478 | AB16: =SUM(E325,E318,E311,E304,E297,E290,E283,E235,E232,E225,E222,E58,E68,E76,E81,E90,E96,E107,E113+E124,E129,E194,E202,E205,E212,E215) -> 4784.1478
B17: MATERIAIS | C17: Materiais | D17: 35950 | E17: =D17-V17 -> 35950 | V17: =SUM(F17:U17) -> 0 | Z17: Consumiveis | AA17: =SUM(D58,D68,D81,D83,D84,D96,D98,D99,D113,D115,D116,D129,D131,D132) -> 2292 | AB17: =SUM(E58,E68,E81,E83,E84,E96,E98,E99,E113,E115,E116,E129,E131,E132) -> 2292
B18: Outros | C18: Outros | D18: 35950 | E18: =D18-V18 -> 35950 | V18: =SUM(F18:U18) -> 0 | Z18: Andamei | AA18: =SUM(D60,D70,D100,D117,D133,D139,D145,D151,D157,D163,D169,D196,D206,D216,D226,D236,D285,D292,D299,D306,D313,D320,D330) -> 1860.5202 | AB18: =SUM(E60,E70,E100,E117,E133,E139,E145,E151,E157,E163,E169,E196,E206,E216,E226,E236,E285,E292,E299,E306,E313,E320,E330) -> 1860.5202
A19: 1.2.1.3 | B19: Desmobilização de Canteiro Completo (Adm, Vestiários, Refeitório, Armazém, etc) | C19: - | D19: 0 | E19: =D19-V19 -> 0 | V19: =SUM(F19:U19) -> 0 | Z19: Caçamba | AA19: =SUM(D101,D118,D134) -> 329.88438 | AB19: =SUM(E101,E118,E134) -> 329.88438
A20: 1.3.1.1 | B20: Administração Local | D20: {=SUM(D21:D22+D25)} -> 6352156.9 | E20: =D20-V20 -> 6352156.9 | V20: =SUM(F20:U20) -> 0 | Z20: Outros | AA20: =SUM(D18,D140,D146,D152,D158,D164,D170,D205,D207,D215,D217,D225,D227,D235,D237,D242:D243,D248:D249,D254:D255,D260:D261,D266:D267,D272:D273,D278:D279,D286,D293,D300,D307,D314,D321) -> 82459.433 | AB20: =SUM(E18,E140,E146,E152,E158,E164,E170,E205,E207,E215,E217,E225,E227,E235,E237,E242:E243,E248:E249,E254:E255,E260:E261,E266:E267,E272:E273,E278:E279,E286,E293,E300,E307,E314,E321) -> 82459.433
B21: MÃO DE OBRA | C21: MÃO DE OBRA | D21: 4808656.9 | E21: =D21-V21 -> 4808656.9 | V21: =SUM(F21:U21) -> 0
B22: EQUIPAMENTOS | C22: EQUIPAMENTOS | D22: 1543500 | E22: =D22-V22 -> 1543500 | V22: =SUM(F22:U22) -> 0 | Z22: total | AA22: =SUM(AA6:AA20) -> 9753707.6 | AB22: =SUM(AB6:AB20) -> 9729439.3
B23: Onibus | C23: Ônibus transporte interno | D23: 1309000 | E23: =D23-V23 -> 1309000 | V23: =SUM(F23:U23) -> 0
B24: Outros | C24: Carro Leves | D24: 234500 | E24: =D24-V24 -> 234500 | V24: =SUM(F24:U24) -> 0
B25: MATERIAIS | C25: Materiais | D25: 0 | E25: =D25-V25 -> 0 | V25: =SUM(F25:U25) -> 0
A26: 2.1.1.1 | B26: Serviços de documentação de obras com time lapse | D26: =SUM(D27:D29) -> 35500 | E26: =D26-V26 -> 35500 | V26: =SUM(F26:U26) -> 0
B27: MÃO DE OBRA | C27: MÃO DE OBRA | D27: 10500 | E27: =D27-V27 -> 10500 | V27: =SUM(F27:U27) -> 0
B28: EQUIPAMENTOS | C28: Locação de Equipamento | D28: 25000 | E28: =D28-V28 -> 25000 | V28: =SUM(F28:U28) -> 0
B29: MATERIAIS | C29: Materiais | D29: 0 | E29: =D29-V29 -> 0 | V29: =SUM(F29:U29) -> 0
A30: 2.1.1.2 | B30: Elaboração de Projetos Detalhados, vistas, cortes etc. ex. projeto de guarda-corpo e condição insegura. | D30: =SUM(D31:D33) -> 1965.625 | E30: =D30-V30 -> 1965.625 | V30: =SUM(F30:U30) -> 0
B31: MÃO DE OBRA | C31: MÃO DE OBRA | D31: 1965.625 | E31: =D31-V31 -> 1965.625 | V31: =SUM(F31:U31) -> 0
B32: EQUIPAMENTOS | C32: EQUIPAMENTOS | D32: 0 | E32: =D32-V32 -> 0 | V32: =SUM(F32:U32) -> 0
B33: MATERIAIS | C33: MATERIAIS | D33: 0 | E33: =D33-V33 -> 0 | V33: =SUM(F33:U33) -> 0
A34: 2.2.1.1.1 | B34: Demolição de concreto armado mecanizado. | D34: =SUM(D35:D37) -> 301.13341 | E34: =D34-V34 -> 301.13341 | V34: =SUM(F34:U34) -> 0
B35: MÃO DE OBRA | C35: MÃO DE OBRA | D35: 173.03991 | E35: =D35-V35 -> 173.03991 | V35: =SUM(F35:U35) -> 0
B36: EQUIPAMENTOS | C36: Maquinas Pesadas | D36: 106.74459 | E36: =D36-V36 -> 106.74459 | V36: =SUM(F36:U36) -> 0
B37: MATERIAIS | C37: MATERIAIS | D37: 21.348917 | E37: =D37-V37 -> 21.348917 | V37: =SUM(F37:U37) -> 0
A38: 2.2.1.2.1 | B38: Carga, transporte e descarga de material proveniente de demolições ou desmontes para a área do CMD - Vale. CAÇAMBAS E CAMINHÃO DA CONTRATADA | D38: =SUM(D39:D41) -> 95.668888 | E38: =D38-V38 -> 95.668888 | V38: =SUM(F38:U38) -> 0
B39: MÃO DE OBRA | C39: MÃO DE OBRA | D39: 53.973704 | E39: =D39-V39 -> 53.973704 | V39: =SUM(F39:U39) -> 0
B40: EQUIPAMENTOS | C40: Maquinas Pesadas | D40: 41.695185 | E40: =D40-V40 -> 41.695185 | V40: =SUM(F40:U40) -> 0
B41: MATERIAIS | C41: MATERIAIS | D41: 0 | E41: =D41-V41 -> 0 | V41: =SUM(F41:U41) -> 0
...
